<?xml version="1.0" ?>
<!-- =================================================================================== -->
<!-- |    This document was autogenerated by xacro from rookie.urdf.xacro              | -->
<!-- |    EDITING THIS FILE BY HAND IS NOT RECOMMENDED                                 | -->
<!-- =================================================================================== -->
<robot name="rookie">
  <!-- approximate -->
  <!-- just a guess -->
  <!-- /Macros -->
  <link name="base_link">
    <visual>
      <geometry>
        <box size="0.226155 0.147 0.079"/>
      </geometry>
    </visual>
    <collision>
      <geometry>
        <box size="0.226155 0.147 0.079"/>
      </geometry>
    </collision>
    <inertial name="base_link_inertia">
      <mass value="2"/>
      <!-- 3D inertia tensor from: https://en.wikipedia.org/wiki/List_of_moments_of_inertia -->
      <inertia ixx="0.009564514004166665" ixy="0.0" ixz="0.0" iyy="0.004641666666666666" iyz="0.0" izz="0.0121258473375"/>
    </inertial>
  </link>
  <link name="front_left_wheel">
    <visual>
      <origin rpy="0.0 0.0 0.0" xyz="0.0 0.0 0.0"/>
      <geometry>
        <mesh filename="package://rookie_description/meshes/Banebots_T81_Wheel.dae"/>
      </geometry>
    </visual>
    <collision>
      <origin rpy="1.570796327 0 0" xyz="0 -0.01016 0"/>
      <geometry>
        <cylinder length="0.02032" radius="0.0492125"/>
      </geometry>
    </collision>
    <inertial name="front_left_wheel_inertia">
      <mass value="0.0992233"/>
      <inertia ixx="6.349061549415349e-05" ixy="0" ixz="0" iyy="6.349061549415349e-05" iyz="0" izz="0.0001201529745373203"/>
    </inertial>
  </link>
  <joint name="front_left_wheel_joint" type="continuous">
    <parent link="base_link"/>
    <child link="front_left_wheel"/>
    <origin rpy="0.0 0.0 0" xyz="0.0645                  0.0973                  -0.010287499999999998"/>
  </joint>
  <link name="front_right_wheel">
    <visual>
      <origin rpy="0.0 0.0 0.0" xyz="0.0 0.0 0.0"/>
      <geometry>
        <mesh filename="package://rookie_description/meshes/Banebots_T81_Wheel.dae"/>
      </geometry>
    </visual>
    <collision>
      <origin rpy="1.570796327 0 0" xyz="0 -0.01016 0"/>
      <geometry>
        <cylinder length="0.02032" radius="0.0492125"/>
      </geometry>
    </collision>
    <inertial name="front_right_wheel_inertia">
      <mass value="0.0992233"/>
      <inertia ixx="6.349061549415349e-05" ixy="0" ixz="0" iyy="6.349061549415349e-05" iyz="0" izz="0.0001201529745373203"/>
    </inertial>
  </link>
  <joint name="front_right_wheel_joint" type="continuous">
    <parent link="base_link"/>
    <child link="front_right_wheel"/>
    <origin rpy="0.0 0.0 3.14159" xyz="0.0645                  -0.0973                  -0.010287499999999998"/>
  </joint>
  <link name="rear_left_wheel">
    <visual>
      <origin rpy="0.0 0.0 0.0" xyz="0.0 0.0 0.0"/>
      <geometry>
        <mesh filename="package://rookie_description/meshes/Banebots_T81_Wheel.dae"/>
      </geometry>
    </visual>
    <collision>
      <origin rpy="1.570796327 0 0" xyz="0 -0.01016 0"/>
      <geometry>
        <cylinder length="0.02032" radius="0.0492125"/>
      </geometry>
    </collision>
    <inertial name="rear_left_wheel_inertia">
      <mass value="0.0992233"/>
      <inertia ixx="6.349061549415349e-05" ixy="0" ixz="0" iyy="6.349061549415349e-05" iyz="0" izz="0.0001201529745373203"/>
    </inertial>
  </link>
  <joint name="rear_left_wheel_joint" type="continuous">
    <parent link="base_link"/>
    <child link="rear_left_wheel"/>
    <origin rpy="0.0 0.0 0" xyz="-0.0645                  0.0973                  -0.010287499999999998"/>
  </joint>
  <link name="rear_right_wheel">
    <visual>
      <origin rpy="0.0 0.0 0.0" xyz="0.0 0.0 0.0"/>
      <geometry>
        <mesh filename="package://rookie_description/meshes/Banebots_T81_Wheel.dae"/>
      </geometry>
    </visual>
    <collision>
      <origin rpy="1.570796327 0 0" xyz="0 -0.01016 0"/>
      <geometry>
        <cylinder length="0.02032" radius="0.0492125"/>
      </geometry>
    </collision>
    <inertial name="rear_right_wheel_inertia">
      <mass value="0.0992233"/>
      <inertia ixx="6.349061549415349e-05" ixy="0" ixz="0" iyy="6.349061549415349e-05" iyz="0" izz="0.0001201529745373203"/>
    </inertial>
  </link>
  <joint name="rear_right_wheel_joint" type="continuous">
    <parent link="base_link"/>
    <child link="rear_right_wheel"/>
    <origin rpy="0.0 0.0 3.14159" xyz="-0.0645                  -0.0973                  -0.010287499999999998"/>
  </joint>
</robot>
