<?xml version="1.0" ?>
<!-- =================================================================================== -->
<!-- |    This document was autogenerated by xacro from rookie.urdf.xacro              | -->
<!-- |    EDITING THIS FILE BY HAND IS NOT RECOMMENDED                                 | -->
<!-- =================================================================================== -->
<robot name="rookie">
  <!-- approximate -->
  <!-- just a guess -->
  <!-- /Macros -->
  <link name="base_link">
    <visual>
      <geometry>
        <box size="0.226155 0.147 0.079"/>
      </geometry>
    </visual>
    <collision>
      <geometry>
        <box size="0.226155 0.147 0.079"/>
      </geometry>
    </collision>
    <inertial name="base_link_inertia">
      <mass value="2"/>
      <!-- 3D inertia tensor from: https://en.wikipedia.org/wiki/List_of_moments_of_inertia -->
      <inertia ixx="0.009564514004166665" ixy="0.0" ixz="0.0" iyy="0.004641666666666666" iyz="0.0" izz="0.0121258473375"/>
    </inertial>
  </link>
  <link name="front_left_wheel">
    <visual>
      <origin rpy="0.0 0.0 0.0" xyz="0.0 0.0 0.0"/>
      <geometry>
        <mesh filename="/home/wfletcher/workspace/install/rookie_description/share/rookie_description/meshes//Banebots_T81_Wheel.dae"/>
      </geometry>
    </visual>
    <collision>
      <origin rpy="1.570796327 0 0" xyz="0 -0.01016 0"/>
      <geometry>
        <cylinder length="0.02032" radius="0.0492125"/>
      </geometry>
    </collision>
    <inertial name="front_left_wheel_inertia">
      <mass value="0.0992233"/>
      <!-- 3D inertia tensor from: https://en.wikipedia.org/wiki/List_of_moments_of_inertia -->
      <inertia ixx="6.349061549415349e-05" ixy="0" ixz="0" iyy="6.349061549415349e-05" iyz="0" izz="0.0001201529745373203"/>
    </inertial>
  </link>
  <joint name="front_left_wheel_joint" type="continuous">
    <parent link="base_link"/>
    <child link="front_left_wheel"/>
    <origin rpy="0.0 0.0 0" xyz="0.0645                  0.0973                  -0.010287499999999998"/>
  </joint>
  <link name="front_right_wheel">
    <visual>
      <origin rpy="0.0 0.0 0.0" xyz="0.0 0.0 0.0"/>
      <geometry>
        <mesh filename="/home/wfletcher/workspace/install/rookie_description/share/rookie_description/meshes//Banebots_T81_Wheel.dae"/>
      </geometry>
    </visual>
    <collision>
      <origin rpy="1.570796327 0 0" xyz="0 -0.01016 0"/>
      <geometry>
        <cylinder length="0.02032" radius="0.0492125"/>
      </geometry>
    </collision>
    <inertial name="front_right_wheel_inertia">
      <mass value="0.0992233"/>
      <!-- 3D inertia tensor from: https://en.wikipedia.org/wiki/List_of_moments_of_inertia -->
      <inertia ixx="6.349061549415349e-05" ixy="0" ixz="0" iyy="6.349061549415349e-05" iyz="0" izz="0.0001201529745373203"/>
    </inertial>
  </link>
  <joint name="front_right_wheel_joint" type="continuous">
    <parent link="base_link"/>
    <child link="front_right_wheel"/>
    <origin rpy="0.0 0.0 3.14159" xyz="0.0645                  -0.0973                  -0.010287499999999998"/>
  </joint>
  <link name="rear_left_wheel">
    <visual>
      <origin rpy="0.0 0.0 0.0" xyz="0.0 0.0 0.0"/>
      <geometry>
        <mesh filename="/home/wfletcher/workspace/install/rookie_description/share/rookie_description/meshes//Banebots_T81_Wheel.dae"/>
      </geometry>
    </visual>
    <collision>
      <origin rpy="1.570796327 0 0" xyz="0 -0.01016 0"/>
      <geometry>
        <cylinder length="0.02032" radius="0.0492125"/>
      </geometry>
    </collision>
    <inertial name="rear_left_wheel_inertia">
      <mass value="0.0992233"/>
      <!-- 3D inertia tensor from: https://en.wikipedia.org/wiki/List_of_moments_of_inertia -->
      <inertia ixx="6.349061549415349e-05" ixy="0" ixz="0" iyy="6.349061549415349e-05" iyz="0" izz="0.0001201529745373203"/>
    </inertial>
  </link>
  <joint name="rear_left_wheel_joint" type="continuous">
    <parent link="base_link"/>
    <child link="rear_left_wheel"/>
    <origin rpy="0.0 0.0 0" xyz="-0.0645                  0.0973                  -0.010287499999999998"/>
  </joint>
  <link name="rear_right_wheel">
    <visual>
      <origin rpy="0.0 0.0 0.0" xyz="0.0 0.0 0.0"/>
      <geometry>
        <mesh filename="/home/wfletcher/workspace/install/rookie_description/share/rookie_description/meshes//Banebots_T81_Wheel.dae"/>
      </geometry>
    </visual>
    <collision>
      <origin rpy="1.570796327 0 0" xyz="0 -0.01016 0"/>
      <geometry>
        <cylinder length="0.02032" radius="0.0492125"/>
      </geometry>
    </collision>
    <inertial name="rear_right_wheel_inertia">
      <mass value="0.0992233"/>
      <!-- 3D inertia tensor from: https://en.wikipedia.org/wiki/List_of_moments_of_inertia -->
      <inertia ixx="6.349061549415349e-05" ixy="0" ixz="0" iyy="6.349061549415349e-05" iyz="0" izz="0.0001201529745373203"/>
    </inertial>
  </link>
  <joint name="rear_right_wheel_joint" type="continuous">
    <parent link="base_link"/>
    <child link="rear_right_wheel"/>
    <origin rpy="0.0 0.0 3.14159" xyz="-0.0645                  -0.0973                  -0.010287499999999998"/>
  </joint>
  <link name="lidar_slamtec_c1">
    <visual>
      <origin rpy="0.0 0.0 0.0" xyz="0.0 0.0 0.0"/>
      <geometry>
        <cylinder length="0.0413" radius="0.0278"/>
      </geometry>
    </visual>
    <collision>
      <geometry>
        <cylinder length="0.0413" radius="0.0278"/>
      </geometry>
    </collision>
  </link>
  <joint name="lidar_joint" type="fixed">
    <parent link="base_link"/>
    <child link="lidar_slamtec_c1"/>
    <origin rpy="0.0 0.0 0" xyz="0 0 0.06015"/>
  </joint>
  <link name="camera">
    <static>true</static>
    <visual name="visual">
      <geometry>
        <box size="0.01 0.05 0.01"/>
      </geometry>
    </visual>
  </link>
  <joint name="camera_joint" type="fixed">
    <parent link="base_link"/>
    <child link="camera"/>
    <origin rpy="0.0 0.0 0" xyz="0.1130775 0 0"/>
  </joint>
  <!-- The plugins we need to be loaded -->
  <gazebo>
    <!-- plugin type "imu" -->
    <plugin filename="gz-sim-imu-system" name="gz::sim::systems::Imu"/>
    <!-- LiDAR ('gpu_lidar') plugin, Camera ('camera') -->
    <plugin filename="gz-sim-sensors-system" name="gz::sim::systems::Sensors"/>
  </gazebo>
  <!-- "Global" sensors, not explicitly attached to any link -->
  <gazebo>
    <!-- Differential drive (skid steer) plugin -->
    <plugin filename="gz-sim-diff-drive-system" name="gz::sim::systems::DiffDrive">
      <update_rate>30</update_rate>
      <left_joint>front_left_wheel_joint</left_joint>
      <left_joint>rear_left_wheel_joint</left_joint>
      <right_joint>front_right_wheel_joint</right_joint>
      <right_joint>rear_right_wheel_joint</right_joint>
      <wheel_separation>0.204</wheel_separation>
      <wheel_radius>0.0492125</wheel_radius>
      <odom_publish_frequency>50</odom_publish_frequency>
      <frame_id>odom</frame_id>
      <topic>cmd_vel</topic>
    </plugin>
  </gazebo>
  <!-- Sensors attached to the base_link -->
  <gazebo reference="base_link">
    <!-- IMU plugin -->
    <sensor name="imu_sensor" type="imu">
      <always_on>1</always_on>
      <update_rate>20</update_rate>
      <visualize>false</visualize>
      <topic>imu</topic>
    </sensor>
  </gazebo>
  <!-- Sensors attached to the lidar_slamtec_c1 link -->
  <gazebo reference="lidar_slamtec_c1">
    <sensor name="lidar_slamtec_c1_sensor" type="gpu_lidar">
      <pose relative_to="lidar_joint">0 0 0 0 0 0</pose>
      <always_on>1</always_on>
      <visualize>true</visualize>
      <topic>lidar</topic>
      <update_rate>10</update_rate>
      <ray>
        <scan>
          <horizontal>
            <samples>640</samples>
            <resolution>1</resolution>
            <min_angle>-1.396263</min_angle>
            <max_angle>1.396263</max_angle>
          </horizontal>
          <vertical>
            <samples>1</samples>
            <resolution>0.01</resolution>
            <min_angle>0</min_angle>
            <max_angle>0</max_angle>
          </vertical>
        </scan>
        <range>
          <min>0.08</min>
          <max>10.0</max>
          <resolution>0.01</resolution>
        </range>
      </ray>
    </sensor>
  </gazebo>
  <gazebo reference="camera">
    <sensor name="camera_sensor" type="camera">
      <camera>
        <horizontal_fov>1.047</horizontal_fov>
        <image>
          <width>320</width>
          <height>240</height>
        </image>
        <clip>
          <near>0.1</near>
          <far>100</far>
        </clip>
      </camera>
      <always_on>1</always_on>
      <update_rate>30</update_rate>
      <visualize>true</visualize>
      <topic>camera</topic>
    </sensor>
  </gazebo>
</robot>
